
The following have been reloaded with a version change:
  1) devel/cuda/12.2 => devel/cuda/12.4

2025-03-06 21:09:57.229664: E external/local_xla/xla/stream_executor/cuda/cuda_fft.cc:477] Unable to register cuFFT factory: Attempting to register factory for plugin cuFFT when one has already been registered
WARNING: All log messages before absl::InitializeLog() is called are written to STDERR
E0000 00:00:1741291797.275480 3686204 cuda_dnn.cc:8310] Unable to register cuDNN factory: Attempting to register factory for plugin cuDNN when one has already been registered
E0000 00:00:1741291797.287645 3686204 cuda_blas.cc:1418] Unable to register cuBLAS factory: Attempting to register factory for plugin cuBLAS when one has already been registered
2025-03-06 21:09:57.370885: I tensorflow/core/platform/cpu_feature_guard.cc:210] This TensorFlow binary is optimized to use available CPU instructions in performance-critical operations.
To enable the following instructions: AVX2 AVX512F AVX512_VNNI FMA, in other operations, rebuild TensorFlow with the appropriate compiler flags.
INFO:root:Starting serial dataset generation...
INFO:root:Generating dataset: Number of obs 100 | Replication 0
INFO:root:Saved X to ../data_generation/output_modified/X_n_100_rep_0.npy
INFO:root:Saved linear_effects to ../data_generation/output_modified/linear_effects_n_100_rep_0.npy
INFO:root:Saved Z to ../data_generation/output_modified/Z_n_100_rep_0.npy
INFO:root:Saved nonlinear_effects to ../data_generation/output_modified/nonlinear_effects_n_100_rep_0.npy
INFO:root:Saved images to ../data_generation/output_modified/images_n_100_rep_0.npy
INFO:root:Saved images_jpg to ../data_generation/output_modified/images_jpg_n_100_rep_0.npy
INFO:root:Generated X, Z, images: n=100, rep=0
2025-03-06 21:10:20.540227: E external/local_xla/xla/stream_executor/cuda/cuda_driver.cc:152] failed call to cuInit: INTERNAL: CUDA error: Failed call to cuInit: CUDA_ERROR_NO_DEVICE: no CUDA-capable device is detected
2025-03-06 21:10:20.540291: I external/local_xla/xla/stream_executor/cuda/cuda_diagnostics.cc:137] retrieving CUDA diagnostic information for host: haicn1706.localdomain
2025-03-06 21:10:20.540306: I external/local_xla/xla/stream_executor/cuda/cuda_diagnostics.cc:144] hostname: haicn1706.localdomain
2025-03-06 21:10:20.540410: I external/local_xla/xla/stream_executor/cuda/cuda_diagnostics.cc:168] libcuda reported version is: 550.54.15
2025-03-06 21:10:20.540438: I external/local_xla/xla/stream_executor/cuda/cuda_diagnostics.cc:172] kernel reported version is: 550.54.15
2025-03-06 21:10:20.540446: I external/local_xla/xla/stream_executor/cuda/cuda_diagnostics.cc:259] kernel version seems to match DSO: 550.54.15
Traceback (most recent call last):
  File "/hkfs/home/haicore/scc/pa6512/PySSDR/data_generation/data_generation_parallel_generalized.py", line 480, in <module>
    scenarios_generate(
  File "/hkfs/home/haicore/scc/pa6512/PySSDR/data_generation/data_generation_parallel_generalized.py", line 423, in scenarios_generate
    generate_task(
  File "/hkfs/home/haicore/scc/pa6512/PySSDR/data_generation/data_generation_parallel_generalized.py", line 317, in generate_task
    unstructured_effects, U_k, psi_k = generate_unstructured_effects(
  File "/hkfs/home/haicore/scc/pa6512/PySSDR/data_generation/data_generation_parallel_generalized.py", line 102, in generate_unstructured_effects
    dnn_model = build_dnn(input_dim)
  File "/hkfs/home/haicore/scc/pa6512/PySSDR/data_generation/data_generation_parallel_generalized.py", line 39, in build_dnn
    model.compile(optimizer='adam', loss='mse', use_bias=False)  # Compile the model
  File "/software/all/jupyter/ai/2025-01-14/lib/python3.9/site-packages/keras/src/utils/traceback_utils.py", line 122, in error_handler
    raise e.with_traceback(filtered_tb) from None
  File "/software/all/jupyter/ai/2025-01-14/lib/python3.9/site-packages/keras/src/utils/tracking.py", line 26, in wrapper
    return fn(*args, **kwargs)
TypeError: compile() got an unexpected keyword argument 'use_bias'
cp: cannot stat '/scratch/slurm_tmpdir/job_1505583/output_modified': No such file or directory
